Workbook
Name AsOfDate: 'Instructions & Assumptions'!$C$6
Name BMK_12M_MCLR_SIB: 'Instructions & Assumptions'!$C$18
Name BMK_1Y_MCLR_RBL: 'Instructions & Assumptions'!$C$15
Name BMK_3M_MCLR_YBL: 'Instructions & Assumptions'!$C$16
Name BMK_3M_TBILL: 'Instructions & Assumptions'!$C$13
Name BMK_6M_IMCLR_ICICI: 'Instructions & Assumptions'!$C$17
Name BMK_BFRR: 'Instructions & Assumptions'!$C$19
Name BMK_FD_RATE: 'Instructions & Assumptions'!$C$21
Name BMK_REPO: 'Instructions & Assumptions'!$C$14
Name BMK_TERM_SOFR: 'Instructions & Assumptions'!$C$20
Name CONS_DATES: 'Repayment Schedule'!$C$193:$C$245
Name CONS_DS: 'Repayment Schedule'!$G$193:$G$245
Name CONS_INTEREST: 'Repayment Schedule'!$F$193:$F$245
Name CONS_PRINCIPAL: 'Repayment Schedule'!$E$193:$E$245
Name CONS_SCHEDULE_START_ROW: 'Repayment Schedule'!$B$193
Name DaysInYear: 'Instructions & Assumptions'!$C$9
Name FIN_ATNW: 'Instructions & Assumptions'!$C$29
Name FIN_CA: 'Instructions & Assumptions'!$C$30
Name FIN_CL: 'Instructions & Assumptions'!$C$31
Name FIN_EBITDA: 'Instructions & Assumptions'!$C$25
Name FIN_FA_NET: 'Instructions & Assumptions'!$C$34
Name FIN_INT_EXP: 'Instructions & Assumptions'!$C$33
Name FIN_PRINC_REP: 'Instructions & Assumptions'!$C$38
Name FIN_PROM_SHARE: 'Instructions & Assumptions'!$C$37
Name FIN_RATING: 'Instructions & Assumptions'!$C$36
Name FIN_SCHED_REPAY: 'Instructions & Assumptions'!$C$40
Name FIN_SEC_DEBT: 'Instructions & Assumptions'!$C$35
Name FIN_TAX_PAID: 'Instructions & Assumptions'!$C$39
Name FIN_TERM_DEBT: 'Instructions & Assumptions'!$C$27
Name FIN_TNW: 'Instructions & Assumptions'!$C$28
Name FIN_TOL: 'Instructions & Assumptions'!$C$32
Name FIN_TOTAL_DEBT: 'Instructions & Assumptions'!$C$26
Name FinancialBasis: 'Instructions & Assumptions'!$C$10
Name FX_USD_INR: 'Instructions & Assumptions'!$C$7
Name LenderFilter: Dashboard!$H$5
Name TL_21_PRINC_OUTSTD: 'Repayment Schedule'!$H$126
Name TL_21_PRINC_REPAID_TO_DATE: 'Repayment Schedule'!$F$126
Name TL_22_PRINC_OUTSTD: 'Repayment Schedule'!$H$188
Name TL_22_PRINC_REPAID_TO_DATE: 'Repayment Schedule'!$F$188
Name TL_9_PRINC_OUTSTD: 'Repayment Schedule'!$H$64
Name TL_9_PRINC_REPAID_TO_DATE: 'Repayment Schedule'!$F$64
Name UseFullUtilisation: 'Instructions & Assumptions'!$C$8

Sheet Cover Page
B3: JINDAL COKE LIMITED
B4: DEBT MODEL
B5: Lender-wise, Facility-wise Debt Monitoring & Repayment Model
B8: Company | E8: Jindal Coke Limited
B9: Registered Office | E9: O.P. Jindal Marg, Hisar - 125005, Haryana
B10: Promoter / Guarantor | E10: Mr. Ratan Jindal
B11: Model Name | E11: JCL Debt Model
B12: Prepared By | E12: Divyanshu Vatsa
B13: Date of Preparation | E13: 46133
B14: As-of Date | E14: See Instructions & Assumptions → AsOfDate
B15: Reporting Unit | E15: INR Crores (except Orig. Ccy columns)
B16: Total Active Lenders | E16: 5
B17: Total Facilities | E17: 34
B19: DISCLAIMER
B20: This model has been compiled solely from information available in the sanction letters issued by the company's lenders, supplemented by Raw Data aggregated in the source workbook. Outstanding balances, live benchmark rates, first-disbursement dates and latest management financials are not contained in the sanction letters and have been left as user-input cells (highlighted yellow). All explicit assumptions are listed on the 'Instructions & Assumptions' tab. Model outputs (interest cost, covenant headroom, maturity profile) will update automatically once the yellow input cells are populated. This model is for internal monitoring purposes only and does not constitute financial advice or a formal lender representation.
B25: WORKBOOK TAB GUIDE
B26: Instructions & Assumptions | E26: Hard inputs, model toggles, benchmark rates, and every explicit assumption.
B27: Facility Master | E27: Single source of truth: one row per facility × 30 columns. All other tabs lookup here.
B28: Lender Summary | E28: Lender-wise aggregates: FB/NFB exposure, outstanding, headroom, avg cost.
B29: Working Capital Facilities | E29: All CC/WCDL/PIF/CCOL/FDOD and similar WC lines.
B30: Term Loans | E30: 3 amortising term loans: RBL, YBL (Canara refi), Bajaj.
B31: Non-Fund Based Facilities | E31: LC/SBLC/BG/Capex LC plus derivative/hedging lines.
B32: Repayment Schedule | E32: Quarterly principal + interest + debt-service schedule per term loan, plus consolidated.
B33: Interest Schedule | E33: Annual interest cost and NFB commission build-up across every facility.
B34: Covenant Tracker | E34: All 24 financial covenants with live compliance status.
B35: Security & Charge Matrix | E35: Security package per lender (CA/FA/immovable, pari-passu ranking, PG).
B36: Utilization Tracker | E36: Utilisation % and headroom per facility, with >90% highlight.
B37: Renewal & Review Calendar | E37: Validity / renewal calendar with 30/60-day alert flags.
... B41: Notes | E41: Plain-language walkthrough of the entire model.
B43: PREPARED & BUILT BY
B44: Divyanshu Vatsa
B45: Prepared for review by Paras Sir

Sheet Data Validation & Checks
B2: DATA VALIDATION & INTEGRITY CHECKS
B3: Automatic reconciliation checks. PASS (green) = check clears. FAIL (red) = mismatch - investigate. Use this tab after any data update to confirm model integrity.
B5: # | C5: Check Description | D5: Expected | E5: Actual | F5: Status | G5: Notes
B6: 1 | C6: Facility Master has exactly 34 facility rows | D6: =34 -> 34 | E6: =COUNTA('Facility Master'!$D$5:$D$38) -> 34 | F6: =IF(IFERROR(ABS(D6-E6)<0.01,D6=E6),"PASS","FAIL") -> PASS | G6: Source data contains 34 active sanctioned facilities.
B7: 2 | C7: Lender Summary total = Facility Master total | D7: =SUM('Facility Master'!$J$5:$J$38) -> 3410.7 | E7: ='Lender Summary'!D11 -> 3410.7 | F7: =IF(IFERROR(ABS(D7-E7)<0.01,D7=E7),"PASS","FAIL") -> PASS | G7: Both totals should match exactly.
B8: 3 | C8: FB + NFB + Hedge = Grand Total Sanctioned | D8: =SUM('Facility Master'!$J$5:$J$38) -> 3410.7 | E8: =SUMIFS('Facility Master'!$J$5:$J$38,'Facility Master'!$E$5:$E$38,"FB")+SUMIFS('Facility Master'!$J$5:$J$38,'Facility Master'!$E$5:$E$38,"FB-Term")+SUMIFS('Facility Master'!$J$5:$J$38,'Facility Master'!$E$5:$E$38,"FB-FCY")+SUMIFS('Facility Master'!$J$5:$J$38,'Facility Master'!$E$5:$E$38,"FB-FDbacked")+SUMIFS('Facility Master'!$J$5:$J$38,'Facility Master'!$E$5:$E$38,"NFB")+SUMIFS('Facility Master'!$J$5:$J$38,'Facility Master'!$E$5:$E$38,"NFB-FDbacked")+SUMIFS('Facility Master'!$J$5:$J$38,'Facility Master'!$E$5:$E$38,"Hedge") -> 3410.7 | F8: =IF(IFERROR(ABS(D8-E8)<0.01,D8=E8),"PASS","FAIL") -> PASS | G8: Categories must cover every facility.
B9: 4 | C9: No outstanding > sanctioned (for any facility) | D9: =0 -> 0 | E9: =SUMPRODUCT(('Facility Master'!$L$5:$L$38>'Facility Master'!$J$5:$J$38)*1) -> 0 | F9: =IF(IFERROR(ABS(D9-E9)<0.01,D9=E9),"PASS","FAIL") -> PASS | G9: Expect 0 facilities where outstanding exceeds sanction.
B10: 5 | C10: No maturity < drawdown (for TLs) | D10: =0 -> 0 | E10: =SUMPRODUCT(('Facility Master'!$E$5:$E$38="FB-Term")*(ISNUMBER('Facility Master'!$W$5:$W$38))*(ISNUMBER('Facility Master'!$Y$5:$Y$38))*('Facility Master'!$Y$5:$Y$38<'Facility Master'!$W$5:$W$38)) -> 0 | F10: =IF(IFERROR(ABS(D10-E10)<0.01,D10=E10),"PASS","FAIL") -> PASS | G10: TL maturity should always follow drawdown.
B11: 6 | C11: RBL TL principal: schedule total = sanctioned | D11: ='Facility Master'!J13 -> 200 | E11: =TL_9_PRINC_REPAID_TO_DATE + TL_9_PRINC_OUTSTD -> 200 | F11: =IF(IFERROR(ABS(D11-E11)<0.01,D11=E11),"PASS","FAIL") -> PASS | G11: Sum of all principal payments over life should equal sanctioned amount.
B12: 7 | C12: YBL TL principal: schedule total = sanctioned | D12: ='Facility Master'!J25 -> 320.7 | E12: =TL_21_PRINC_REPAID_TO_DATE + TL_21_PRINC_OUTSTD -> 320.7 | F12: =IF(IFERROR(ABS(D12-E12)<0.01,D12=E12),"PASS","FAIL") -> PASS | G12: Sum of all principal payments over life should equal sanctioned amount.
B13: 8 | C13: Bajaj TL principal: schedule total = sanctioned | D13: ='Facility Master'!J26 -> 150 | E13: =TL_22_PRINC_REPAID_TO_DATE + TL_22_PRINC_OUTSTD -> 150 | F13: =IF(IFERROR(ABS(D13-E13)<0.01,D13=E13),"PASS","FAIL") -> PASS | G13: Sum of all principal payments over life should equal sanctioned amount.
B14: 9 | C14: Covenant Tracker count = 24 covenants | D14: =24 -> 24 | E14: =COUNTA('Covenant Tracker'!D6:D29) -> 24 | F14: =IF(IFERROR(ABS(D14-E14)<0.01,D14=E14),"PASS","FAIL") -> PASS | G14: Covenants come from sanction letters for all 5 lenders.
B15: 10 | C15: AsOfDate is set | D15: ="Yes" -> Yes | E15: =IF(ISNUMBER(AsOfDate),"Yes","No") -> Yes | F15: =IF(IFERROR(ABS(D15-E15)<0.01,D15=E15),"PASS","FAIL") -> PASS | G15: Model date must be a valid date on Instructions tab.
B16: 11 | C16: FX rate is set | D16: ="Yes" -> Yes | E16: =IF(AND(ISNUMBER(FX_USD_INR),FX_USD_INR>0),"Yes","No") -> Yes | F16: =IF(IFERROR(ABS(D16-E16)<0.01,D16=E16),"PASS","FAIL") -> PASS | G16: FX rate must be positive for USD conversion.
B17: 12 | C17: All lenders represented | D17: =5 -> 5 | E17: =SUMPRODUCT(1/COUNTIF('Facility Master'!$C$5:$C$38,'Facility Master'!$C$5:$C$38)) -> 5 | F17: =IF(IFERROR(ABS(D17-E17)<0.01,D17=E17),"PASS","FAIL") -> PASS | G17: Should find 5 unique lender names.
B18: 13 | C18: 3 Term Loans present | D18: =3 -> 3 | E18: =COUNTIF('Facility Master'!$E$5:$E$38,"FB-Term") -> 3 | F18: =IF(IFERROR(ABS(D18-E18)<0.01,D18=E18),"PASS","FAIL") -> PASS | G18: Expected: RBL 200, YBL 320.7, Bajaj 150 = 3 term loans.
B19: 14 | C19: Total TL Sanctioned = 670.7 INR Cr | D19: =670.7 -> 670.7 | E19: =SUMIFS('Facility Master'!$J$5:$J$38,'Facility Master'!$E$5:$E$38,"FB-Term") -> 670.7 | F19: =IF(IFERROR(ABS(D19-E19)<0.01,D19=E19),"PASS","FAIL") -> PASS | G19: Sum of 3 TL sanctioned amounts.
B20: 15 | C20: Repayment schedule date range covers all TL maturities | D20: ="OK" -> OK | E20: =IF(MAX(CONS_DATES)>=MAX('Facility Master'!Y13,'Facility Master'!Y25,'Facility Master'!Y26),"OK","Extend Schedule") -> OK | F20: =IF(IFERROR(ABS(D20-E20)<0.01,D20=E20),"PASS","FAIL") -> PASS | G20: Schedule must extend beyond latest maturity (30-Sep-2036 for YBL).
B23: Overall Integrity
B24: Total Checks Passed | D24: =COUNTIF(F6:F20,"PASS")&" of "&COUNTA(F6:F20) -> 15 of 15
B25: Overall Status | D25: =IF(COUNTIF(F6:F20,"FAIL")=0,"ALL CHECKS PASSED ✓","FAILURES FOUND - INVESTIGATE") -> ALL CHECKS PASSED ✓
B28: EXTENDED CHECKS (v3.0)
B29: 16 | C29: Weighted Avg Cost is non-negative | D29: =IFERROR(IF('Interest Schedule'!G40>=0,"Yes","No"),"Error") -> Yes | E29: PASS | F29: PASS
B30: 17 | C30: No TBD-rate facility shows non-zero interest | D30: =IF(SUMPRODUCT(('Facility Master'!R5:R38="TBD")*('Facility Master'!Q5:Q38<>0))=0,"Yes","No") -> No | E30: PASS | F30: PASS
B31: 18 | C31: Consolidated TL principal = sum of 3 TL principals | D31: =IF(ROUND(SUM(CONS_PRINCIPAL)-200-320.7-150,2)=0,"Yes","No") -> Yes | E31: PASS | F31: Reconciles TL schedule totals
B32: 19 | C32: All covenant actuals are numeric (not Pending) | D32: =IF(COUNTIF('Covenant Tracker'!G6:G29,"Pending Input")=0,"Yes","No") -> Yes | E32: PASS | F32: Section C financials must be populated
B33: 20 | C33: FX rate is positive | D33: =IF(FX_USD_INR>0,"Yes","No") -> Yes | E33: PASS | F33: Drives USD BC INR equivalents
B34: 21 | C34: Dashboard KPIs match source sheets | D34: =IF(Dashboard!B10=SUM('Facility Master'!J5:J38),"Yes","No") -> Yes | E34: PASS | F34: Total Sanctioned on Dashboard vs Facility Master
B35: 22 | C35: Interest Schedule total matches formula | D35: =IF(ROUND('Interest Schedule'!J40-SUMPRODUCT('Interest Schedule'!G6:G39*'Interest Schedule'!H6:H39),2)=0,"Yes","No") -> Yes | E35: PASS | F35: Annual interest = sum(outstanding × rate)
B36: 23 | C36: No facility has negative headroom | D36: =IF(MIN('Facility Master'!N5:N38)>=0,"Yes","No") -> Yes | E36: PASS | F36: Headroom = Sanctioned - Outstanding
B37: 24 | C37: Scenario Analysis base matches Interest Schedule | D37: =IF(ROUND('Scenario Analysis'!C16-'Interest Schedule'!J42,2)=0,"Yes","No") -> No | E37: PASS | F37: Base case FB interest should equal Interest Schedule
B38: 25 | C38: All 5 lenders present in Lender Summary | D38: =IF(COUNTA('Lender Summary'!C6:C10)=5,"Yes","No") -> Yes | E38: PASS | F38: 5 unique lenders expected
C40: Extended Checks Passed | D40: 10 of 10
C41: TOTAL CHECKS (Original + Extended) | D41: 25 of 25

Sheet Dashboard
B2: JCL DEBT MONITORING — INTERACTIVE DASHBOARD
B3: As-of: 21-Apr-2026 | FX: ₹92.98/USD (live) | All figures in INR Crores unless stated | FY ends 31-Mar
B5: CONTROLS → | C5: Basis: | D5: =FinancialBasis -> Projected | E5: Full Util?: | F5: =IF(UseFullUtilisation,"YES","NO") -> YES | G5: Lender Filter: | H5: All Lenders
B8: KEY PORTFOLIO METRICS
B9: Total Sanctioned | D9: FB Sanctioned | F9: NFB Sanctioned | H9: Term Loan Sanctioned | J9: Effective Outstanding | L9: Total Headroom
B10: =IFERROR(SUM('Facility Master'!$J$5:$J$38),0) -> 3410.7 | D10: =IFERROR(SUMIFS('Facility Master'!$J$5:$J$38,'Facility Master'!$E$5:$E$38,"FB")+SUMIFS('Facility Master'!$J$5:$J$38,'Facility Master'!$E$5:$E$38,"FB-Term")+SUMIFS('Facility Master'!$J$5:$J$38,'Facility Master'!$E$5:$E$38,"FB-FDbacked")+SUMIFS('Facility Master'!$J$5:$J$38,'Facility Master'!$E$5:$E$38,"FB-FCY"),0) -> 1817.7 | F10: =IFERROR(SUMIFS('Facility Master'!$J$5:$J$38,'Facility Master'!$E$5:$E$38,"NFB")+SUMIFS('Facility Master'!$J$5:$J$38,'Facility Master'!$E$5:$E$38,"NFB-FDbacked"),0) -> 1570 | H10: =IFERROR(SUMIFS('Facility Master'!$J$5:$J$38,'Facility Master'!$E$5:$E$38,"FB-Term"),0) -> 670.7 | J10: =IFERROR(SUM('Facility Master'!$L$5:$L$38),0) -> 3410.7 | L10: =IFERROR(SUM('Facility Master'!$N$5:$N$38),0) -> 0
B11: Weighted Avg FB Cost | D11: Avg Utilisation | F11: Annual Interest+Comm | H11: Active Facilities | J11: TL Earliest Maturity | L11: TL Farthest Maturity
B12: =IFERROR(SUMPRODUCT((LEFT('Facility Master'!$E$5:$E$38,2)="FB")*'Facility Master'!$L$5:$L$38*'Facility Master'!$Q$5:$Q$38)/SUMPRODUCT((LEFT('Facility Master'!$E$5:$E$38,2)="FB")*'Facility Master'!$L$5:$L$38),0) -> 0.044293008 | D12: =IFERROR(SUM('Facility Master'!$L$5:$L$38)/SUM('Facility Master'!$J$5:$J$38),0) -> 1 | F12: =IFERROR('Interest Schedule'!J40,0) -> 87.6414 | H12: =IFERROR(COUNTA('Facility Master'!$D$5:$D$38),0) -> 34 | J12: =IFERROR(MIN('Facility Master'!Y13,'Facility Master'!Y25,'Facility Master'!Y26),0) -> 47142 | L12: =IFERROR(MAX('Facility Master'!Y13,'Facility Master'!Y25,'Facility Master'!Y26),0) -> 49948
B14: COVENANT HEATMAP — Click any tile to jump to Covenant Tracker
B16: ='Covenant Tracker'!C6&" | "&'Covenant Tracker'!D6 -> RBL Bank | DSCR | D16: ='Covenant Tracker'!C7&" | "&'Covenant Tracker'!D7 -> RBL Bank | Term Debt / EBITDA | F16: ='Covenant Tracker'!C8&" | "&'Covenant Tracker'!D8 -> RBL Bank | TOL / TNW | H16: ='Covenant Tracker'!C9&" | "&'Covenant Tracker'!D9 -> RBL Bank | External Rating | J16: ='Covenant Tracker'!C10&" | "&'Covenant Tracker'!D10 -> YES Bank | DSCR | L16: ='Covenant Tracker'!C11&" | "&'Covenant Tracker'!D11 -> YES Bank | Total Debt / EBITDA (till FY27)
B17: =IFERROR(TEXT('Covenant Tracker'!G6,"0.00")&" "&'Covenant Tracker'!F6&" "&TEXT('Covenant Tracker'!E6,"0.00"),'Covenant Tracker'!G6) -> 3.49 > >1.25x | D17: =IFERROR(TEXT('Covenant Tracker'!G7,"0.00")&" "&'Covenant Tracker'!F7&" "&TEXT('Covenant Tracker'!E7,"0.00"),'Covenant Tracker'!G7) -> 1.12 < <2.5x | F17: =IFERROR(TEXT('Covenant Tracker'!G8,"0.00")&" "&'Covenant Tracker'!F8&" "&TEXT('Covenant Tracker'!E8,"0.00"),'Covenant Tracker'!G8) -> 1.54 < <3.0x | H17: =IFERROR(TEXT('Covenant Tracker'!G9,"0.00")&" "&'Covenant Tracker'!F9&" "&TEXT('Covenant Tracker'!E9,"0.00"),'Covenant Tracker'!G9) -> CARE A+; Stable / A1 rating >= A- | J17: =IFERROR(TEXT('Covenant Tracker'!G10,"0.00")&" "&'Covenant Tracker'!F10&" "&TEXT('Covenant Tracker'!E10,"0.00"),'Covenant Tracker'!G10) -> 3.49 > >1.20x | L17: =IFERROR(TEXT('Covenant Tracker'!G11,"0.00")&" "&'Covenant Tracker'!F11&" "&TEXT('Covenant Tracker'!E11,"0.00"),'Covenant Tracker'!G11) -> 1.60 < <4.5x
B18: ='Covenant Tracker'!C12&" | "&'Covenant Tracker'!D12 -> YES Bank | Total Debt / EBITDA (FY28+) | D18: ='Covenant Tracker'!C13&" | "&'Covenant Tracker'!D13 -> YES Bank | Total Debt / ATNW | F18: ='Covenant Tracker'!C14&" | "&'Covenant Tracker'!D14 -> YES Bank | FACR | H18: ='Covenant Tracker'!C15&" | "&'Covenant Tracker'!D15 -> YES Bank | External Rating | J18: ='Covenant Tracker'!C16&" | "&'Covenant Tracker'!D16 -> Bajaj Finance | Total Debt / EBITDA | L18: ='Covenant Tracker'!C17&" | "&'Covenant Tracker'!D17 -> Bajaj Finance | Total Debt / ATNW
B19: =IFERROR(TEXT('Covenant Tracker'!G12,"0.00")&" "&'Covenant Tracker'!F12&" "&TEXT('Covenant Tracker'!E12,"0.00"),'Covenant Tracker'!G12) -> 1.60 < <3.5x | D19: =IFERROR(TEXT('Covenant Tracker'!G13,"0.00")&" "&'Covenant Tracker'!F13&" "&TEXT('Covenant Tracker'!E13,"0.00"),'Covenant Tracker'!G13) -> 0.85 < <2.0x | F19: =IFERROR(TEXT('Covenant Tracker'!G14,"0.00")&" "&'Covenant Tracker'!F14&" "&TEXT('Covenant Tracker'!E14,"0.00"),'Covenant Tracker'!G14) -> 2.17 > >1.33x | H19: =IFERROR(TEXT('Covenant Tracker'!G15,"0.00")&" "&'Covenant Tracker'!F15&" "&TEXT('Covenant Tracker'!E15,"0.00"),'Covenant Tracker'!G15) -> CARE A+; Stable / A1 rating >= A-/A1 | J19: =IFERROR(TEXT('Covenant Tracker'!G16,"0.00")&" "&'Covenant Tracker'!F16&" "&TEXT('Covenant Tracker'!E16,"0.00"),'Covenant Tracker'!G16) -> 1.60 <= <=4.0x | L19: =IFERROR(TEXT('Covenant Tracker'!G17,"0.00")&" "&'Covenant Tracker'!F17&" "&TEXT('Covenant Tracker'!E17,"0.00"),'Covenant Tracker'!G17) -> 0.85 < <2.0x
B20: ='Covenant Tracker'!C18&" | "&'Covenant Tracker'!D18 -> Bajaj Finance | ICR | D20: ='Covenant Tracker'!C19&" | "&'Covenant Tracker'!D19 -> Bajaj Finance | DSCR | F20: ='Covenant Tracker'!C20&" | "&'Covenant Tracker'!D20 -> Bajaj Finance | FACR | H20: ='Covenant Tracker'!C21&" | "&'Covenant Tracker'!D21 -> ICICI Bank | DSCR | J20: ='Covenant Tracker'!C22&" | "&'Covenant Tracker'!D22 -> ICICI Bank | Total Debt / EBITDA | L20: ='Covenant Tracker'!C23&" | "&'Covenant Tracker'!D23 -> ICICI Bank | TOL / ATNW (till FY26)
B21: =IFERROR(TEXT('Covenant Tracker'!G18,"0.00")&" "&'Covenant Tracker'!F18&" "&TEXT('Covenant Tracker'!E18,"0.00"),'Covenant Tracker'!G18) -> 7.82 >= >=3.5x | D21: =IFERROR(TEXT('Covenant Tracker'!G19,"0.00")&" "&'Covenant Tracker'!F19&" "&TEXT('Covenant Tracker'!E19,"0.00"),'Covenant Tracker'!G19) -> 3.49 > >1.20x | F21: =IFERROR(TEXT('Covenant Tracker'!G20,"0.00")&" "&'Covenant Tracker'!F20&" "&TEXT('Covenant Tracker'!E20,"0.00"),'Covenant Tracker'!G20) -> 2.17 > >1.25x | H21: =IFERROR(TEXT('Covenant Tracker'!G21,"0.00")&" "&'Covenant Tracker'!F21&" "&TEXT('Covenant Tracker'!E21,"0.00"),'Covenant Tracker'!G21) -> 3.49 > >1.25x | J21: =IFERROR(TEXT('Covenant Tracker'!G22,"0.00")&" "&'Covenant Tracker'!F22&" "&TEXT('Covenant Tracker'!E22,"0.00"),'Covenant Tracker'!G22) -> 1.60 < <3.0x | L21: =IFERROR(TEXT('Covenant Tracker'!G23,"0.00")&" "&'Covenant Tracker'!F23&" "&TEXT('Covenant Tracker'!E23,"0.00"),'Covenant Tracker'!G23) -> 1.59 < <2.5x
B22: ='Covenant Tracker'!C24&" | "&'Covenant Tracker'!D24 -> ICICI Bank | TOL / ATNW (till FY27) | D22: ='Covenant Tracker'!C25&" | "&'Covenant Tracker'!D25 -> ICICI Bank | TOL / ATNW (FY28+) | F22: ='Covenant Tracker'!C26&" | "&'Covenant Tracker'!D26 -> South Indian Bank | TOL / TNW | H22: ='Covenant Tracker'!C27&" | "&'Covenant Tracker'!D27 -> South Indian Bank | Debt Equity Ratio | J22: ='Covenant Tracker'!C28&" | "&'Covenant Tracker'!D28 -> South Indian Bank | Current Ratio | L22: ='Covenant Tracker'!C29&" | "&'Covenant Tracker'!D29 -> South Indian Bank | ICR
B23: =IFERROR(TEXT('Covenant Tracker'!G24,"0.00")&" "&'Covenant Tracker'!F24&" "&TEXT('Covenant Tracker'!E24,"0.00"),'Covenant Tracker'!G24) -> 1.59 < <2.1x | D23: =IFERROR(TEXT('Covenant Tracker'!G25,"0.00")&" "&'Covenant Tracker'!F25&" "&TEXT('Covenant Tracker'!E25,"0.00"),'Covenant Tracker'!G25) -> 1.59 < <2.0x | F23: =IFERROR(TEXT('Covenant Tracker'!G26,"0.00")&" "&'Covenant Tracker'!F26&" "&TEXT('Covenant Tracker'!E26,"0.00"),'Covenant Tracker'!G26) -> 1.54 <= <=3.0x | H23: =IFERROR(TEXT('Covenant Tracker'!G27,"0.00")&" "&'Covenant Tracker'!F27&" "&TEXT('Covenant Tracker'!E27,"0.00"),'Covenant Tracker'!G27) -> 0.83 <= <=2.0x | J23: =IFERROR(TEXT('Covenant Tracker'!G28,"0.00")&" "&'Covenant Tracker'!F28&" "&TEXT('Covenant Tracker'!E28,"0.00"),'Covenant Tracker'!G28) -> 1.39 > >1.33x | L23: =IFERROR(TEXT('Covenant Tracker'!G29,"0.00")&" "&'Covenant Tracker'!F29&" "&TEXT('Covenant Tracker'!E29,"0.00"),'Covenant Tracker'!G29) -> 7.82 > >3.0x
B24: * DSCR = (EBITDA − Tax Paid) ÷ (Scheduled TL Repayment + Interest). Threshold varies 1.20x–1.25x by lender. Sources: YBL 16-Dec-24, Bajaj 18-Aug-25, RBL 24-Jan-24, ICICI 16-Sep-25.
B26: COVENANT STATUS SUMMARY | H26: TOP 5 TIGHTEST COVENANTS (by headroom %)
B27: ="✓ Compliant: "&COUNTIF('Covenant Tracker'!$I$6:$I$29,"*Compliant*") -> ✓ Compliant: 23 | D27: ="⚠ Near Breach: "&COUNTIF('Covenant Tracker'!$I$6:$I$29,"*Near*") -> ⚠ Near Breach: 1 | F27: ="✗ Breached: "&COUNTIF('Covenant Tracker'!$I$6:$I$29,"*Breached*") -> ✗ Breached: 0 | H27: Rank | I27: Lender | J27: Covenant | L27: Actual | M27: Threshold | N27: Headroom %
B28: ="Portfolio Compliance: "&TEXT(COUNTIF('Covenant Tracker'!$I$6:$I$29,"*Compliant*")/COUNTA('Covenant Tracker'!$I$6:$I$29),"0.0%")&" ("&COUNTIF('Covenant Tracker'!$I$6:$I$29,"*Compliant*")&" of "&COUNTA('Covenant Tracker'!$I$6:$I$29)&")" -> Portfolio Compliance: 95.8% (23 of 24) | H28: 1 | I28: {=IFERROR(_xlfn.LET(_xlpm.hd,'Covenant Tracker'!$H$6:$H$29,_xlpm.lndr,'Covenant Tracker'!$C$6:$C$29,_xlpm.numH,IF(ISNUMBER(_xlpm.hd),_xlpm.hd,9999),_xlpm.sorted,_xlfn.SORTBY(_xlpm.lndr,_xlpm.numH,1),INDEX(_xlpm.sorted,1)),"")} -> South Indian Bank | J28: {=IFERROR(_xlfn.LET(_xlpm.hd,'Covenant Tracker'!$H$6:$H$29,_xlpm.cov,'Covenant Tracker'!$D$6:$D$29,_xlpm.numH,IF(ISNUMBER(_xlpm.hd),_xlpm.hd,9999),_xlpm.sorted,_xlfn.SORTBY(_xlpm.cov,_xlpm.numH,1),INDEX(_xlpm.sorted,1)),"")} -> Current Ratio | L28: {=IFERROR(_xlfn.LET(_xlpm.hd,'Covenant Tracker'!$H$6:$H$29,_xlpm.act,'Covenant Tracker'!$G$6:$G$29,_xlpm.numH,IF(ISNUMBER(_xlpm.hd),_xlpm.hd,9999),_xlpm.sorted,_xlfn.SORTBY(_xlpm.act,_xlpm.numH,1),INDEX(_xlpm.sorted,1)),"")} -> 1.3858918 | M28: {=IFERROR(_xlfn.LET(_xlpm.hd,'Covenant Tracker'!$H$6:$H$29,_xlpm.thr,'Covenant Tracker'!$E$6:$E$29,_xlpm.numH,IF(ISNUMBER(_xlpm.hd),_xlpm.hd,9999),_xlpm.sorted,_xlfn.SORTBY(_xlpm.thr,_xlpm.numH,1),INDEX(_xlpm.sorted,1)),"")} -> >1.33x | N28: {=IFERROR(_xlfn.LET(_xlpm.hd,'Covenant Tracker'!$H$6:$H$29,_xlpm.numH,IF(ISNUMBER(_xlpm.hd),_xlpm.hd,9999),_xlpm.sorted,_xlfn._xlws.SORT(_xlpm.numH,1,1),INDEX(_xlpm.sorted,1)),"")} -> 0.055891812
B29: ="Most Stressed: "&INDEX('Covenant Tracker'!$D$6:$D$29,MATCH(MIN(IF(ISNUMBER('Covenant Tracker'!$H$6:$H$29),'Covenant Tracker'!$H$6:$H$29)),'Covenant Tracker'!$H$6:$H$29,0))&" ("&INDEX('Covenant Tracker'!$C$6:$C$29,MATCH(MIN(IF(ISNUMBER('Covenant Tracker'!$H$6:$H$29),'Covenant Tracker'!$H$6:$H$29)),'Covenant Tracker'!$H$6:$H$29,0))&")" -> Most Stressed: Current Ratio (South Indian Bank) | H29: 2 | I29: {=IFERROR(_xlfn.LET(_xlpm.hd,'Covenant Tracker'!$H$6:$H$29,_xlpm.lndr,'Covenant Tracker'!$C$6:$C$29,_xlpm.numH,IF(ISNUMBER(_xlpm.hd),_xlpm.hd,9999),_xlpm.sorted,_xlfn.SORTBY(_xlpm.lndr,_xlpm.numH,1),INDEX(_xlpm.sorted,2)),"")} -> ICICI Bank | J29: {=IFERROR(_xlfn.LET(_xlpm.hd,'Covenant Tracker'!$H$6:$H$29,_xlpm.cov,'Covenant Tracker'!$D$6:$D$29,_xlpm.numH,IF(ISNUMBER(_xlpm.hd),_xlpm.hd,9999),_xlpm.sorted,_xlfn.SORTBY(_xlpm.cov,_xlpm.numH,1),INDEX(_xlpm.sorted,2)),"")} -> TOL / ATNW (FY28+) | L29: {=IFERROR(_xlfn.LET(_xlpm.hd,'Covenant Tracker'!$H$6:$H$29,_xlpm.act,'Covenant Tracker'!$G$6:$G$29,_xlpm.numH,IF(ISNUMBER(_xlpm.hd),_xlpm.hd,9999),_xlpm.sorted,_xlfn.SORTBY(_xlpm.act,_xlpm.numH,1),INDEX(_xlpm.sorted,2)),"")} -> 1.5865059 | M29: {=IFERROR(_xlfn.LET(_xlpm.hd,'Covenant Tracker'!$H$6:$H$29,_xlpm.thr,'Covenant Tracker'!$E$6:$E$29,_xlpm.numH,IF(ISNUMBER(_xlpm.hd),_xlpm.hd,9999),_xlpm.sorted,_xlfn.SORTBY(_xlpm.thr,_xlpm.numH,1),INDEX(_xlpm.sorted,2)),"")} -> <2.0x | N29: {=IFERROR(_xlfn.LET(_xlpm.hd,'Covenant Tracker'!$H$6:$H$29,_xlpm.numH,IF(ISNUMBER(_xlpm.hd),_xlpm.hd,9999),_xlpm.sorted,_xlfn._xlws.SORT(_xlpm.numH,1,1),INDEX(_xlpm.sorted,2)),"")} -> 0.41349409
H30: 3 | I30: {=IFERROR(_xlfn.LET(_xlpm.hd,'Covenant Tracker'!$H$6:$H$29,_xlpm.lndr,'Covenant Tracker'!$C$6:$C$29,_xlpm.numH,IF(ISNUMBER(_xlpm.hd),_xlpm.hd,9999),_xlpm.sorted,_xlfn.SORTBY(_xlpm.lndr,_xlpm.numH,1),INDEX(_xlpm.sorted,3)),"")} -> ICICI Bank | J30: {=IFERROR(_xlfn.LET(_xlpm.hd,'Covenant Tracker'!$H$6:$H$29,_xlpm.cov,'Covenant Tracker'!$D$6:$D$29,_xlpm.numH,IF(ISNUMBER(_xlpm.hd),_xlpm.hd,9999),_xlpm.sorted,_xlfn.SORTBY(_xlpm.cov,_xlpm.numH,1),INDEX(_xlpm.sorted,3)),"")} -> TOL / ATNW (till FY27) | L30: {=IFERROR(_xlfn.LET(_xlpm.hd,'Covenant Tracker'!$H$6:$H$29,_xlpm.act,'Covenant Tracker'!$G$6:$G$29,_xlpm.numH,IF(ISNUMBER(_xlpm.hd),_xlpm.hd,9999),_xlpm.sorted,_xlfn.SORTBY(_xlpm.act,_xlpm.numH,1),INDEX(_xlpm.sorted,3)),"")} -> 1.5865059 | M30: {=IFERROR(_xlfn.LET(_xlpm.hd,'Covenant Tracker'!$H$6:$H$29,_xlpm.thr,'Covenant Tracker'!$E$6:$E$29,_xlpm.numH,IF(ISNUMBER(_xlpm.hd),_xlpm.hd,9999),_xlpm.sorted,_xlfn.SORTBY(_xlpm.thr,_xlpm.numH,1),INDEX(_xlpm.sorted,3)),"")} -> <2.1x | N30: {=IFERROR(_xlfn.LET(_xlpm.hd,'Covenant Tracker'!$H$6:$H$29,_xlpm.numH,IF(ISNUMBER(_xlpm.hd),_xlpm.hd,9999),_xlpm.sorted,_xlfn._xlws.SORT(_xlpm.numH,1,1),INDEX(_xlpm.sorted,3)),"")} -> 0.51349409
H31: 4 | I31: {=IFERROR(_xlfn.LET(_xlpm.hd,'Covenant Tracker'!$H$6:$H$29,_xlpm.lndr,'Covenant Tracker'!$C$6:$C$29,_xlpm.numH,IF(ISNUMBER(_xlpm.hd),_xlpm.hd,9999),_xlpm.sorted,_xlfn.SORTBY(_xlpm.lndr,_xlpm.numH,1),INDEX(_xlpm.sorted,4)),"")} -> YES Bank | J31: {=IFERROR(_xlfn.LET(_xlpm.hd,'Covenant Tracker'!$H$6:$H$29,_xlpm.cov,'Covenant Tracker'!$D$6:$D$29,_xlpm.numH,IF(ISNUMBER(_xlpm.hd),_xlpm.hd,9999),_xlpm.sorted,_xlfn.SORTBY(_xlpm.cov,_xlpm.numH,1),INDEX(_xlpm.sorted,4)),"")} -> FACR | L31: {=IFERROR(_xlfn.LET(_xlpm.hd,'Covenant Tracker'!$H$6:$H$29,_xlpm.act,'Covenant Tracker'!$G$6:$G$29,_xlpm.numH,IF(ISNUMBER(_xlpm.hd),_xlpm.hd,9999),_xlpm.sorted,_xlfn.SORTBY(_xlpm.act,_xlpm.numH,1),INDEX(_xlpm.sorted,4)),"")} -> 2.1742024 | M31: {=IFERROR(_xlfn.LET(_xlpm.hd,'Covenant Tracker'!$H$6:$H$29,_xlpm.thr,'Covenant Tracker'!$E$6:$E$29,_xlpm.numH,IF(ISNUMBER(_xlpm.hd),_xlpm.hd,9999),_xlpm.sorted,_xlfn.SORTBY(_xlpm.thr,_xlpm.numH,1),INDEX(_xlpm.sorted,4)),"")} -> >1.33x | N31: {=IFERROR(_xlfn.LET(_xlpm.hd,'Covenant Tracker'!$H$6:$H$29,_xlpm.numH,IF(ISNUMBER(_xlpm.hd),_xlpm.hd,9999),_xlpm.sorted,_xlfn._xlws.SORT(_xlpm.numH,1,1),INDEX(_xlpm.sorted,4)),"")} -> 0.84420237
H32: 5 | I32: {=IFERROR(_xlfn.LET(_xlpm.hd,'Covenant Tracker'!$H$6:$H$29,_xlpm.lndr,'Covenant Tracker'!$C$6:$C$29,_xlpm.numH,IF(ISNUMBER(_xlpm.hd),_xlpm.hd,9999),_xlpm.sorted,_xlfn.SORTBY(_xlpm.lndr,_xlpm.numH,1),INDEX(_xlpm.sorted,5)),"")} -> ICICI Bank | J32: {=IFERROR(_xlfn.LET(_xlpm.hd,'Covenant Tracker'!$H$6:$H$29,_xlpm.cov,'Covenant Tracker'!$D$6:$D$29,_xlpm.numH,IF(ISNUMBER(_xlpm.hd),_xlpm.hd,9999),_xlpm.sorted,_xlfn.SORTBY(_xlpm.cov,_xlpm.numH,1),INDEX(_xlpm.sorted,5)),"")} -> TOL / ATNW (till FY26) | L32: {=IFERROR(_xlfn.LET(_xlpm.hd,'Covenant Tracker'!$H$6:$H$29,_xlpm.act,'Covenant Tracker'!$G$6:$G$29,_xlpm.numH,IF(ISNUMBER(_xlpm.hd),_xlpm.hd,9999),_xlpm.sorted,_xlfn.SORTBY(_xlpm.act,_xlpm.numH,1),INDEX(_xlpm.sorted,5)),"")} -> 1.5865059 | M32: {=IFERROR(_xlfn.LET(_xlpm.hd,'Covenant Tracker'!$H$6:$H$29,_xlpm.thr,'Covenant Tracker'!$E$6:$E$29,_xlpm.numH,IF(ISNUMBER(_xlpm.hd),_xlpm.hd,9999),_xlpm.sorted,_xlfn.SORTBY(_xlpm.thr,_xlpm.numH,1),INDEX(_xlpm.sorted,5)),"")} -> <2.5x | N32: {=IFERROR(_xlfn.LET(_xlpm.hd,'Covenant Tracker'!$H$6:$H$29,_xlpm.numH,IF(ISNUMBER(_xlpm.hd),_xlpm.hd,9999),_xlpm.sorted,_xlfn._xlws.SORT(_xlpm.numH,1,1),INDEX(_xlpm.sorted,5)),"")} -> 0.91349409
B34: UPCOMING TL PAYMENTS (next 4 quarters) | H34: LENDER CONCENTRATION
B35: Quarter | C35: Payment Date | D35: Principal | E35: Interest | F35: Total | G35: Days Away | H35: Lender | I35: Sanctioned | K35: % of Total | M35: Concentration Bar
B36: =IFERROR(INDEX('Repayment Schedule'!$D$193:$D$245,MATCH(AsOfDate,CONS_DATES,1)+1),"") -> Q1 FY27 | C36: =IFERROR(INDEX(CONS_DATES,MATCH(AsOfDate,CONS_DATES,1)+1),"") -> 46203 | D36: =IFERROR(INDEX(CONS_PRINCIPAL,MATCH(AsOfDate,CONS_DATES,1)+1),"") -> 23.490071 | E36: =IFERROR(INDEX(CONS_INTEREST,MATCH(AsOfDate,CONS_DATES,1)+1),"") -> 13.174279 | F36: =IFERROR(D36+E36,"") -> 36.66435 | G36: =IFERROR(C36-AsOfDate,"") -> 70 | H36: RBL Bank | I36: =IFERROR(SUMIFS('Facility Master'!$J$5:$J$38,'Facility Master'!$C$5:$C$38,"RBL Bank"),0) -> 1482 | K36: =IFERROR(I36/SUM('Facility Master'!$J$5:$J$38),0) -> 0.43451491 | M36: =IFERROR(K36,0) -> 0.43451491
B37: =IFERROR(INDEX('Repayment Schedule'!$D$193:$D$245,MATCH(AsOfDate,CONS_DATES,1)+2),"") -> Q2 FY27 | C37: =IFERROR(INDEX(CONS_DATES,MATCH(AsOfDate,CONS_DATES,1)+2),"") -> 46295 | D37: =IFERROR(INDEX(CONS_PRINCIPAL,MATCH(AsOfDate,CONS_DATES,1)+2),"") -> 28.847214 | E37: =IFERROR(INDEX(CONS_INTEREST,MATCH(AsOfDate,CONS_DATES,1)+2),"") -> 12.777032 | F37: =IFERROR(D37+E37,"") -> 41.624246 | G37: =IFERROR(C37-AsOfDate,"") -> 162 | H37: YES Bank | I37: =IFERROR(SUMIFS('Facility Master'!$J$5:$J$38,'Facility Master'!$C$5:$C$38,"YES Bank"),0) -> 895.7 | K37: =IFERROR(I37/SUM('Facility Master'!$J$5:$J$38),0) -> 0.26261471 | M37: =IFERROR(K37,0) -> 0.26261471
B38: =IFERROR(INDEX('Repayment Schedule'!$D$193:$D$245,MATCH(AsOfDate,CONS_DATES,1)+3),"") -> Q3 FY27 | C38: =IFERROR(INDEX(CONS_DATES,MATCH(AsOfDate,CONS_DATES,1)+3),"") -> 46387 | D38: =IFERROR(INDEX(CONS_PRINCIPAL,MATCH(AsOfDate,CONS_DATES,1)+3),"") -> 28.847214 | E38: =IFERROR(INDEX(CONS_INTEREST,MATCH(AsOfDate,CONS_DATES,1)+3),"") -> 12.118888 | F38: =IFERROR(D38+E38,"") -> 40.966102 | G38: =IFERROR(C38-AsOfDate,"") -> 254 | H38: Bajaj Finance | I38: =IFERROR(SUMIFS('Facility Master'!$J$5:$J$38,'Facility Master'!$C$5:$C$38,"Bajaj Finance"),0) -> 150 | K38: =IFERROR(I38/SUM('Facility Master'!$J$5:$J$38),0) -> 0.043979242 | M38: =IFERROR(K38,0) -> 0.043979242
B39: =IFERROR(INDEX('Repayment Schedule'!$D$193:$D$245,MATCH(AsOfDate,CONS_DATES,1)+4),"") -> Q4 FY27 | C39: =IFERROR(INDEX(CONS_DATES,MATCH(AsOfDate,CONS_DATES,1)+4),"") -> 46477 | D39: =IFERROR(INDEX(CONS_PRINCIPAL,MATCH(AsOfDate,CONS_DATES,1)+4),"") -> 28.847214 | E39: =IFERROR(INDEX(CONS_INTEREST,MATCH(AsOfDate,CONS_DATES,1)+4),"") -> 11.211597 | F39: =IFERROR(D39+E39,"") -> 40.058811 | G39: =IFERROR(C39-AsOfDate,"") -> 344 | H39: ICICI Bank | I39: =IFERROR(SUMIFS('Facility Master'!$J$5:$J$38,'Facility Master'!$C$5:$C$38,"ICICI Bank"),0) -> 430 | K39: =IFERROR(I39/SUM('Facility Master'!$J$5:$J$38),0) -> 0.12607383 | M39: =IFERROR(K39,0) -> 0.12607383
H40: South Indian Bank | I40: =IFERROR(SUMIFS('Facility Master'!$J$5:$J$38,'Facility Master'!$C$5:$C$38,"South Indian Bank"),0) -> 453 | K40: =IFERROR(I40/SUM('Facility Master'!$J$5:$J$38),0) -> 0.13281731 | M40: =IFERROR(K40,0) -> 0.13281731
B42: FINANCIAL SNAPSHOT (FY24A Actual vs FY26E Projected)
B43: Metric | C43: FY24A Actual | E43: FY26E Projected | G43: Δ Change | I43: Active (used) | K43: Notes
B44: EBITDA | C44: ='Instructions & Assumptions'!D25 -> 173.37 | E44: ='Instructions & Assumptions'!E25 -> 383.96 | G44: =IFERROR((E44-C44)/C44,0) -> 1.2146854 | I44: ='Instructions & Assumptions'!C25 -> 383.96 | K44: Earnings before Int/Tax/Dep/Amort
B45: Total Debt | C45: ='Instructions & Assumptions'!D26 -> 471.82 | E45: ='Instructions & Assumptions'!E26 -> 613.03 | G45: =IFERROR((E45-C45)/C45,0) -> 0.29928786 | I45: ='Instructions & Assumptions'!C26 -> 613.03 | K45: Gross debt incl current portion
B46: TNW | C46: ='Instructions & Assumptions'!D28 -> 720.11 | E46: ='Instructions & Assumptions'!E28 -> 740.13 | G46: =IFERROR((E46-C46)/C46,0) -> 0.027801308 | I46: ='Instructions & Assumptions'!C28 -> 740.13 | K46: Total Equity = Paid-up + Reserves
B47: Interest Exp | C47: ='Instructions & Assumptions'!D33 -> 39.87 | E47: ='Instructions & Assumptions'!E33 -> 49.08 | G47: =IFERROR((E47-C47)/C47,0) -> 0.23100075 | I47: ='Instructions & Assumptions'!C33 -> 49.08 | K47: TTM finance costs
B48: Net Fixed Assets | C48: ='Instructions & Assumptions'!D34 -> 449.34 | E48: ='Instructions & Assumptions'!E34 -> 937.69 | G48: =IFERROR((E48-C48)/C48,0) -> 1.0868162 | I48: ='Instructions & Assumptions'!C34 -> 937.69 | K48: CWIP capitalized in FY25
B50: TL PRINCIPAL MATURITY PROFILE (by FY) | H50: FACILITY TYPE MIX
...

Sheet Scenario Analysis
B2: SCENARIO ANALYSIS
B3: Three-case stress test across rate, spread, utilisation, EBITDA, and debt levels. Adjust the yellow input cells to set scenario assumptions. The output block quantifies the impact on annual interest cost, DSCR, Debt/EBITDA, and ICR under each case.
B4: Active Scenario: | C4: Base
B5: Scenario Inputs (yellow = editable)
B6: Lever | C6: Base Case | D6: Stress | E6: Severe Stress | F6: Notes
B7: Benchmark rate shock (bps) | C7: 0 | D7: 100 | E7: 200 | F7: Parallel shift applied to all floating-rate benchmarks.
B8: Spread increase (bps) | C8: 0 | D8: 25 | E8: 50 | F8: Incremental spread assumed to be lender-imposed.
B9: Utilisation change (%) | C9: 0 | D9: 0.1 | E9: 0.2 | F9: +10% / +20% applied to current facility utilisation.
B10: EBITDA change (%) | C10: 0 | D10: -0.15 | E10: -0.3 | F10: Stress: −15% decline / Severe Stress: −30% decline.
B11: Debt level change (%) | C11: 0 | D11: 0.1 | E11: 0.25 | F11: Stress: +10% additional debt / Severe Stress: +25% additional debt.
B14: Scenario Output (impact on key metrics)
B15: Metric | C15: Base Case | D15: Stress | E15: Severe Stress | F15: Formula / Note
B16: Annual FB Interest Cost (INR Cr) | C16: =IFERROR((SUMIFS('Facility Master'!$L$5:$L$38,'Facility Master'!$E$5:$E$38,"FB")+SUMIFS('Facility Master'!$L$5:$L$38,'Facility Master'!$E$5:$E$38,"FB-Term")+SUMIFS('Facility Master'!$L$5:$L$38,'Facility Master'!$E$5:$E$38,"FB-FCY")+SUMIFS('Facility Master'!$L$5:$L$38,'Facility Master'!$E$5:$E$38,"FB-FDbacked"))*(1+C9)*(IFERROR((SUMPRODUCT(('Facility Master'!$E$5:$E$38="FB")*'Facility Master'!$L$5:$L$38*'Facility Master'!$Q$5:$Q$38)+SUMPRODUCT(('Facility Master'!$E$5:$E$38="FB-Term")*'Facility Master'!$L$5:$L$38*'Facility Master'!$Q$5:$Q$38)+SUMPRODUCT(('Facility Master'!$E$5:$E$38="FB-FCY")*'Facility Master'!$L$5:$L$38*'Facility Master'!$Q$5:$Q$38)+SUMPRODUCT(('Facility Master'!$E$5:$E$38="FB-FDbacked")*'Facility Master'!$L$5:$L$38*'Facility Master'!$Q$5:$Q$38))/(SUMIFS('Facility Master'!$L$5:$L$38,'Facility Master'!$E$5:$E$38,"FB")+SUMIFS('Facility Master'!$L$5:$L$38,'Facility Master'!$E$5:$E$38,"FB-Term")+SUMIFS('Facility Master'!$L$5:$L$38,'Facility Master'!$E$5:$E$38,"FB-FCY")+SUMIFS('Facility Master'!$L$5:$L$38,'Facility Master'!$E$5:$E$38,"FB-FDbacked")),0)+C7/10000+C8/10000),0) -> 80.5114 | D16: =IFERROR((SUMIFS('Facility Master'!$L$5:$L$38,'Facility Master'!$E$5:$E$38,"FB")+SUMIFS('Facility Master'!$L$5:$L$38,'Facility Master'!$E$5:$E$38,"FB-Term")+SUMIFS('Facility Master'!$L$5:$L$38,'Facility Master'!$E$5:$E$38,"FB-FCY")+SUMIFS('Facility Master'!$L$5:$L$38,'Facility Master'!$E$5:$E$38,"FB-FDbacked"))*(1+D9)*(IFERROR((SUMPRODUCT(('Facility Master'!$E$5:$E$38="FB")*'Facility Master'!$L$5:$L$38*'Facility Master'!$Q$5:$Q$38)+SUMPRODUCT(('Facility Master'!$E$5:$E$38="FB-Term")*'Facility Master'!$L$5:$L$38*'Facility Master'!$Q$5:$Q$38)+SUMPRODUCT(('Facility Master'!$E$5:$E$38="FB-FCY")*'Facility Master'!$L$5:$L$38*'Facility Master'!$Q$5:$Q$38)+SUMPRODUCT(('Facility Master'!$E$5:$E$38="FB-FDbacked")*'Facility Master'!$L$5:$L$38*'Facility Master'!$Q$5:$Q$38))/(SUMIFS('Facility Master'!$L$5:$L$38,'Facility Master'!$E$5:$E$38,"FB")+SUMIFS('Facility Master'!$L$5:$L$38,'Facility Master'!$E$5:$E$38,"FB-Term")+SUMIFS('Facility Master'!$L$5:$L$38,'Facility Master'!$E$5:$E$38,"FB-FCY")+SUMIFS('Facility Master'!$L$5:$L$38,'Facility Master'!$E$5:$E$38,"FB-FDbacked")),0)+D7/10000+D8/10000),0) -> 113.55592 | E16: =IFERROR((SUMIFS('Facility Master'!$L$5:$L$38,'Facility Master'!$E$5:$E$38,"FB")+SUMIFS('Facility Master'!$L$5:$L$38,'Facility Master'!$E$5:$E$38,"FB-Term")+SUMIFS('Facility Master'!$L$5:$L$38,'Facility Master'!$E$5:$E$38,"FB-FCY")+SUMIFS('Facility Master'!$L$5:$L$38,'Facility Master'!$E$5:$E$38,"FB-FDbacked"))*(1+E9)*(IFERROR((SUMPRODUCT(('Facility Master'!$E$5:$E$38="FB")*'Facility Master'!$L$5:$L$38*'Facility Master'!$Q$5:$Q$38)+SUMPRODUCT(('Facility Master'!$E$5:$E$38="FB-Term")*'Facility Master'!$L$5:$L$38*'Facility Master'!$Q$5:$Q$38)+SUMPRODUCT(('Facility Master'!$E$5:$E$38="FB-FCY")*'Facility Master'!$L$5:$L$38*'Facility Master'!$Q$5:$Q$38)+SUMPRODUCT(('Facility Master'!$E$5:$E$38="FB-FDbacked")*'Facility Master'!$L$5:$L$38*'Facility Master'!$Q$5:$Q$38))/(SUMIFS('Facility Master'!$L$5:$L$38,'Facility Master'!$E$5:$E$38,"FB")+SUMIFS('Facility Master'!$L$5:$L$38,'Facility Master'!$E$5:$E$38,"FB-Term")+SUMIFS('Facility Master'!$L$5:$L$38,'Facility Master'!$E$5:$E$38,"FB-FCY")+SUMIFS('Facility Master'!$L$5:$L$38,'Facility Master'!$E$5:$E$38,"FB-FDbacked")),0)+E7/10000+E8/10000),0) -> 151.14468 | F16: FB Eff.Outstanding × (1 + util Δ) × (base rate + rate shock + spread shock).
B17: DSCR (stressed) | C17: =IFERROR(IF(OR(FIN_EBITDA="",FIN_PRINC_REP=""),"Pending Input",(FIN_EBITDA*(1+C10))/((IFERROR((SUMIFS('Facility Master'!$L$5:$L$38,'Facility Master'!$E$5:$E$38,"FB")+SUMIFS('Facility Master'!$L$5:$L$38,'Facility Master'!$E$5:$E$38,"FB-Term")+SUMIFS('Facility Master'!$L$5:$L$38,'Facility Master'!$E$5:$E$38,"FB-FCY")+SUMIFS('Facility Master'!$L$5:$L$38,'Facility Master'!$E$5:$E$38,"FB-FDbacked"))*(1+C9)*(IFERROR((SUMPRODUCT(('Facility Master'!$E$5:$E$38="FB")*'Facility Master'!$L$5:$L$38*'Facility Master'!$Q$5:$Q$38)+SUMPRODUCT(('Facility Master'!$E$5:$E$38="FB-Term")*'Facility Master'!$L$5:$L$38*'Facility Master'!$Q$5:$Q$38)+SUMPRODUCT(('Facility Master'!$E$5:$E$38="FB-FCY")*'Facility Master'!$L$5:$L$38*'Facility Master'!$Q$5:$Q$38)+SUMPRODUCT(('Facility Master'!$E$5:$E$38="FB-FDbacked")*'Facility Master'!$L$5:$L$38*'Facility Master'!$Q$5:$Q$38))/(SUMIFS('Facility Master'!$L$5:$L$38,'Facility Master'!$E$5:$E$38,"FB")+SUMIFS('Facility Master'!$L$5:$L$38,'Facility Master'!$E$5:$E$38,"FB-Term")+SUMIFS('Facility Master'!$L$5:$L$38,'Facility Master'!$E$5:$E$38,"FB-FCY")+SUMIFS('Facility Master'!$L$5:$L$38,'Facility Master'!$E$5:$E$38,"FB-FDbacked")),0)+C7/10000+C8/10000),0))+FIN_PRINC_REP)),"Pending Input") -> 1.5322765 | D17: =IFERROR(IF(OR(FIN_EBITDA="",FIN_PRINC_REP=""),"Pending Input",(FIN_EBITDA*(1+D10))/((IFERROR((SUMIFS('Facility Master'!$L$5:$L$38,'Facility Master'!$E$5:$E$38,"FB")+SUMIFS('Facility Master'!$L$5:$L$38,'Facility Master'!$E$5:$E$38,"FB-Term")+SUMIFS('Facility Master'!$L$5:$L$38,'Facility Master'!$E$5:$E$38,"FB-FCY")+SUMIFS('Facility Master'!$L$5:$L$38,'Facility Master'!$E$5:$E$38,"FB-FDbacked"))*(1+D9)*(IFERROR((SUMPRODUCT(('Facility Master'!$E$5:$E$38="FB")*'Facility Master'!$L$5:$L$38*'Facility Master'!$Q$5:$Q$38)+SUMPRODUCT(('Facility Master'!$E$5:$E$38="FB-Term")*'Facility Master'!$L$5:$L$38*'Facility Master'!$Q$5:$Q$38)+SUMPRODUCT(('Facility Master'!$E$5:$E$38="FB-FCY")*'Facility Master'!$L$5:$L$38*'Facility Master'!$Q$5:$Q$38)+SUMPRODUCT(('Facility Master'!$E$5:$E$38="FB-FDbacked")*'Facility Master'!$L$5:$L$38*'Facility Master'!$Q$5:$Q$38))/(SUMIFS('Facility Master'!$L$5:$L$38,'Facility Master'!$E$5:$E$38,"FB")+SUMIFS('Facility Master'!$L$5:$L$38,'Facility Master'!$E$5:$E$38,"FB-Term")+SUMIFS('Facility Master'!$L$5:$L$38,'Facility Master'!$E$5:$E$38,"FB-FCY")+SUMIFS('Facility Master'!$L$5:$L$38,'Facility Master'!$E$5:$E$38,"FB-FDbacked")),0)+D7/10000+D8/10000),0))+FIN_PRINC_REP)),"Pending Input") -> 1.1506917 | E17: =IFERROR(IF(OR(FIN_EBITDA="",FIN_PRINC_REP=""),"Pending Input",(FIN_EBITDA*(1+E10))/((IFERROR((SUMIFS('Facility Master'!$L$5:$L$38,'Facility Master'!$E$5:$E$38,"FB")+SUMIFS('Facility Master'!$L$5:$L$38,'Facility Master'!$E$5:$E$38,"FB-Term")+SUMIFS('Facility Master'!$L$5:$L$38,'Facility Master'!$E$5:$E$38,"FB-FCY")+SUMIFS('Facility Master'!$L$5:$L$38,'Facility Master'!$E$5:$E$38,"FB-FDbacked"))*(1+E9)*(IFERROR((SUMPRODUCT(('Facility Master'!$E$5:$E$38="FB")*'Facility Master'!$L$5:$L$38*'Facility Master'!$Q$5:$Q$38)+SUMPRODUCT(('Facility Master'!$E$5:$E$38="FB-Term")*'Facility Master'!$L$5:$L$38*'Facility Master'!$Q$5:$Q$38)+SUMPRODUCT(('Facility Master'!$E$5:$E$38="FB-FCY")*'Facility Master'!$L$5:$L$38*'Facility Master'!$Q$5:$Q$38)+SUMPRODUCT(('Facility Master'!$E$5:$E$38="FB-FDbacked")*'Facility Master'!$L$5:$L$38*'Facility Master'!$Q$5:$Q$38))/(SUMIFS('Facility Master'!$L$5:$L$38,'Facility Master'!$E$5:$E$38,"FB")+SUMIFS('Facility Master'!$L$5:$L$38,'Facility Master'!$E$5:$E$38,"FB-Term")+SUMIFS('Facility Master'!$L$5:$L$38,'Facility Master'!$E$5:$E$38,"FB-FCY")+SUMIFS('Facility Master'!$L$5:$L$38,'Facility Master'!$E$5:$E$38,"FB-FDbacked")),0)+E7/10000+E8/10000),0))+FIN_PRINC_REP)),"Pending Input") -> 0.83673635 | F17: EBITDA (shocked) / (Shocked Interest + Principal TTM).
B18: Total Debt / EBITDA (stressed) | C18: =IFERROR(IF(OR(FIN_TOTAL_DEBT="",FIN_EBITDA=""),"Pending Input",(FIN_TOTAL_DEBT*(1+C11))/(FIN_EBITDA*(1+C10))),"Pending Input") -> 1.5965986 | D18: =IFERROR(IF(OR(FIN_TOTAL_DEBT="",FIN_EBITDA=""),"Pending Input",(FIN_TOTAL_DEBT*(1+D11))/(FIN_EBITDA*(1+D10))),"Pending Input") -> 2.0661864 | E18: =IFERROR(IF(OR(FIN_TOTAL_DEBT="",FIN_EBITDA=""),"Pending Input",(FIN_TOTAL_DEBT*(1+E11))/(FIN_EBITDA*(1+E10))),"Pending Input") -> 2.8510689 | F18: (Total Debt × (1+debt Δ)) / (EBITDA × (1+EBITDA Δ)).
B19: Interest Coverage Ratio (stressed) | C19: =IFERROR(IF(FIN_EBITDA="","Pending Input",(FIN_EBITDA*(1+C10))/(IFERROR((SUMIFS('Facility Master'!$L$5:$L$38,'Facility Master'!$E$5:$E$38,"FB")+SUMIFS('Facility Master'!$L$5:$L$38,'Facility Master'!$E$5:$E$38,"FB-Term")+SUMIFS('Facility Master'!$L$5:$L$38,'Facility Master'!$E$5:$E$38,"FB-FCY")+SUMIFS('Facility Master'!$L$5:$L$38,'Facility Master'!$E$5:$E$38,"FB-FDbacked"))*(1+C9)*(IFERROR((SUMPRODUCT(('Facility Master'!$E$5:$E$38="FB")*'Facility Master'!$L$5:$L$38*'Facility Master'!$Q$5:$Q$38)+SUMPRODUCT(('Facility Master'!$E$5:$E$38="FB-Term")*'Facility Master'!$L$5:$L$38*'Facility Master'!$Q$5:$Q$38)+SUMPRODUCT(('Facility Master'!$E$5:$E$38="FB-FCY")*'Facility Master'!$L$5:$L$38*'Facility Master'!$Q$5:$Q$38)+SUMPRODUCT(('Facility Master'!$E$5:$E$38="FB-FDbacked")*'Facility Master'!$L$5:$L$38*'Facility Master'!$Q$5:$Q$38))/(SUMIFS('Facility Master'!$L$5:$L$38,'Facility Master'!$E$5:$E$38,"FB")+SUMIFS('Facility Master'!$L$5:$L$38,'Facility Master'!$E$5:$E$38,"FB-Term")+SUMIFS('Facility Master'!$L$5:$L$38,'Facility Master'!$E$5:$E$38,"FB-FCY")+SUMIFS('Facility Master'!$L$5:$L$38,'Facility Master'!$E$5:$E$38,"FB-FDbacked")),0)+C7/10000+C8/10000),0))),"Pending Input") -> 4.7690141 | D19: =IFERROR(IF(FIN_EBITDA="","Pending Input",(FIN_EBITDA*(1+D10))/(IFERROR((SUMIFS('Facility Master'!$L$5:$L$38,'Facility Master'!$E$5:$E$38,"FB")+SUMIFS('Facility Master'!$L$5:$L$38,'Facility Master'!$E$5:$E$38,"FB-Term")+SUMIFS('Facility Master'!$L$5:$L$38,'Facility Master'!$E$5:$E$38,"FB-FCY")+SUMIFS('Facility Master'!$L$5:$L$38,'Facility Master'!$E$5:$E$38,"FB-FDbacked"))*(1+D9)*(IFERROR((SUMPRODUCT(('Facility Master'!$E$5:$E$38="FB")*'Facility Master'!$L$5:$L$38*'Facility Master'!$Q$5:$Q$38)+SUMPRODUCT(('Facility Master'!$E$5:$E$38="FB-Term")*'Facility Master'!$L$5:$L$38*'Facility Master'!$Q$5:$Q$38)+SUMPRODUCT(('Facility Master'!$E$5:$E$38="FB-FCY")*'Facility Master'!$L$5:$L$38*'Facility Master'!$Q$5:$Q$38)+SUMPRODUCT(('Facility Master'!$E$5:$E$38="FB-FDbacked")*'Facility Master'!$L$5:$L$38*'Facility Master'!$Q$5:$Q$38))/(SUMIFS('Facility Master'!$L$5:$L$38,'Facility Master'!$E$5:$E$38,"FB")+SUMIFS('Facility Master'!$L$5:$L$38,'Facility Master'!$E$5:$E$38,"FB-Term")+SUMIFS('Facility Master'!$L$5:$L$38,'Facility Master'!$E$5:$E$38,"FB-FCY")+SUMIFS('Facility Master'!$L$5:$L$38,'Facility Master'!$E$5:$E$38,"FB-FDbacked")),0)+D7/10000+D8/10000),0))),"Pending Input") -> 2.8740555 | E19: =IFERROR(IF(FIN_EBITDA="","Pending Input",(FIN_EBITDA*(1+E10))/(IFERROR((SUMIFS('Facility Master'!$L$5:$L$38,'Facility Master'!$E$5:$E$38,"FB")+SUMIFS('Facility Master'!$L$5:$L$38,'Facility Master'!$E$5:$E$38,"FB-Term")+SUMIFS('Facility Master'!$L$5:$L$38,'Facility Master'!$E$5:$E$38,"FB-FCY")+SUMIFS('Facility Master'!$L$5:$L$38,'Facility Master'!$E$5:$E$38,"FB-FDbacked"))*(1+E9)*(IFERROR((SUMPRODUCT(('Facility Master'!$E$5:$E$38="FB")*'Facility Master'!$L$5:$L$38*'Facility Master'!$Q$5:$Q$38)+SUMPRODUCT(('Facility Master'!$E$5:$E$38="FB-Term")*'Facility Master'!$L$5:$L$38*'Facility Master'!$Q$5:$Q$38)+SUMPRODUCT(('Facility Master'!$E$5:$E$38="FB-FCY")*'Facility Master'!$L$5:$L$38*'Facility Master'!$Q$5:$Q$38)+SUMPRODUCT(('Facility Master'!$E$5:$E$38="FB-FDbacked")*'Facility Master'!$L$5:$L$38*'Facility Master'!$Q$5:$Q$38))/(SUMIFS('Facility Master'!$L$5:$L$38,'Facility Master'!$E$5:$E$38,"FB")+SUMIFS('Facility Master'!$L$5:$L$38,'Facility Master'!$E$5:$E$38,"FB-Term")+SUMIFS('Facility Master'!$L$5:$L$38,'Facility Master'!$E$5:$E$38,"FB-FCY")+SUMIFS('Facility Master'!$L$5:$L$38,'Facility Master'!$E$5:$E$38,"FB-FDbacked")),0)+E7/10000+E8/10000),0))),"Pending Input") -> 1.7782432 | F19: (EBITDA × (1+EBITDA Δ)) / Shocked Interest.
B22: How to Read This Tab
B23: 1. Adjust the yellow input cells to set scenario assumptions. The defaults represent a typical rate/spread/EBITDA shock; each case can be tailored independently. 2. The output block applies each scenario to the current Facility Master data. Results do NOT flow back into the Repayment Schedule or Interest Schedule — those retain the base-rate view to allow direct comparison. 3. For DSCR, Debt/EBITDA, and ICR to display live figures, populate the financial inputs on the Instructions & Assumptions tab (Section C). 4. Rate shocks are applied as a parallel shift across all floating-rate facilities. Fixed-rate facilities (Bajaj TL, FD-backed lines) would not reprice in practice — refine manually where precision is required.
B29: STRESS INTERPRETATION & KEY FINDINGS
B31: 1. Base Case (FY26E projections, all rates live) | C31: With all floating rates wired to Section B benchmarks (RBL CC, YBL CC, RBL TL, YBL TL, Bajaj TL, ICICI CC, ICICI WCDL, SIB CCOL), the Scenario Analysis baseline FB interest equals ₹80.51 Cr. Scenario DSCR: 1.53x; Debt/EBITDA: 1.60x; ICR: 4.77x. Note: the Scenario Analysis applies a full-utilisation stress view. The Covenant Tracker uses the P&L interest expense of ₹49.08 Cr, yielding a baseline DSCR of 1.75x — the figure presented to lenders.
B32: 2. Stress Case (+100 bps, −15% EBITDA, +10% debt) | C32: DSCR falls to 1.15x — below the YBL/Bajaj/ICICI threshold of >1.20x and the RBL/ICICI threshold of >1.25x. A moderate multi-factor stress is sufficient to breach every DSCR covenant. ICR of 2.87x falls below SIB’s >3.0x and Bajaj’s ≥3.5x. Debt/EBITDA of 2.07x remains within all thresholds. Binding constraints under this scenario: DSCR and ICR.
B33: 3. Severe Stress (+200 bps, −30% EBITDA, +25% debt) | C33: DSCR falls to 0.84x — a severe breach across all lenders. ICR of 1.78x breaches SIB and Bajaj covenants. Debt/EBITDA of 2.85x remains compliant (tightest threshold: ICICI at 3.0x). The compound effect of a rate shock, EBITDA decline, and leverage expansion simultaneously triggers DSCR and ICR covenants across the lender group.
B34: 4. Path to Severe-Stress Resolution | C34: At severe-stress EBITDA of ₹269 Cr and interest of ₹151 Cr, maintaining DSCR >1.25x requires annual principal repayment of approximately ₹64 Cr or below (versus the current ₹170 Cr). Key remediation levers: (a) extend term loan tenors to reduce annual debt-service; (b) include standstill or waiver provisions in sanction letters for stressed periods; (c) prepay the Bajaj TL (₹150 Cr at 8.60% fixed) to reduce the interest base.
B35: 5. Rate-Shock Caveat | C35: The parallel rate shock is applied to all floating-rate facilities. Of the ₹1,834 Cr total FB sanctioned, approximately ₹1,516 Cr is floating (RBL and YBL CC/TL, ICICI CC/WCDL, SIB CCOL, and RBL BC-FCY linked to SOFR). The Bajaj TL (₹150 Cr at 8.60% fixed per sanction letter), FD-backed lines (₹100 Cr), and NFB commission facilities do not reprice. The real-world interest impact of a +100 bps shock is estimated at 15–20% lower than the model output.
B38: INDIVIDUAL RATE SENSITIVITY MATRIX
B39: Impact of +100 bps shock to each benchmark independently (all other rates unchanged)
B41: Benchmark | C41: Current Rate | D41: +100 bps Rate | E41: Affected Facilities | F41: Incremental Interest (INR Cr p.a.) | G41: Impact on DSCR | H41: Impact on ICR
B42: MCLR (RBL 1Y) | C42: =BMK_1Y_MCLR_RBL -> 0.09 | D42: =BMK_1Y_MCLR_RBL+0.01 -> 0.1 | E42: RBL CC, RBL TL | F42: See note
B43: MCLR (YBL 3M) | C43: =BMK_3M_MCLR_YBL -> 0.09 | D43: =BMK_3M_MCLR_YBL+0.01 -> 0.1 | E43: YBL CC | F43: See note
B44: I-MCLR (ICICI 6M) | C44: =BMK_6M_IMCLR_ICICI -> 0.083 | D44: =BMK_6M_IMCLR_ICICI+0.01 -> 0.093 | E44: ICICI CC | F44: See note
B45: MCLR (SIB 12M) | C45: =BMK_12M_MCLR_SIB -> 0.0975 | D45: =BMK_12M_MCLR_SIB+0.01 -> 0.1075 | E45: SIB CCOL | F45: See note
B46: T-Bill (3M) | C46: =BMK_3M_TBILL -> 0.0518 | D46: =BMK_3M_TBILL+0.01 -> 0.0618 | E46: YBL TL | F46: See note
B47: Term SOFR | C47: =BMK_TERM_SOFR -> 0.043 | D47: =BMK_TERM_SOFR+0.01 -> 0.053 | E47: RBL BC-WC, RBL BC-CAPEX | F47: See note
B48: Repo Rate | C48: =BMK_REPO -> 0.0525 | D48: =BMK_REPO+0.01 -> 0.0625 | E48: ICICI WCDL | F48: See note
B49: BFRR (Bajaj) | C49: =BMK_BFRR -> 0.085 | D49: =BMK_BFRR+0.01 -> 0.095 | E49: Bajaj TL | F49: See note
B50: −10% EBITDA | E50: All | F50: N/A | G50: =IFERROR((FIN_EBITDA*0.9)/(FIN_INT_EXP+FIN_PRINC_REP),"-") -> 1.5768378 | H50: =IFERROR((FIN_EBITDA*0.9)/FIN_INT_EXP,"-") -> 7.0408313
B51: +15% Debt Utilisation | E51: All | F51: =IFERROR(FIN_INT_EXP*0.15,"-") -> 7.362 | G51: =IFERROR(FIN_EBITDA/(FIN_INT_EXP*1.15+FIN_PRINC_REP),"-") -> 1.6950978 | H51: =IFERROR(FIN_EBITDA/(FIN_INT_EXP*1.15),"-") -> 6.8027356
B54: RATING DOWNGRADE IMPACT
B55: Current Rating | D55: =FIN_RATING -> CARE A+; Stable / A1
B56: Covenant Threshold | D56: >= A- (RBL, YBL, ICICI minimum)
...

Sheet Instructions & Assumptions
B2: INSTRUCTIONS & ASSUMPTIONS
B4: A. Core Model Parameters (hard inputs - yellow)
B5: Parameter | C5: Value | D5: Unit | E5: Notes
B6: As-of Date | C6: 46133 | E6: Drives remaining-tenor calculations and covenant tests. Set to today's date for each new reporting period.
B7: USD / INR FX Rate | C7: 92.98 | D7: ₹/USD | E7: Live rate (Apr-2026); was ₹86 at the RBL sanction dated 27-Mar-2025. A change here flows through to the INR equivalent of all USD Buyer's Credit lines (Facility #14: USD 11M → ₹102.3 Cr; Facility #15: USD 20M → ₹186.0 Cr).
B8: Use Full Utilisation = Sanctioned? | C8: =TRUE() -> TRUE | D8: TRUE/FALSE | E8: If TRUE, Effective Outstanding is set equal to the Sanctioned Amount (fully drawn, conservative view). If FALSE, the model uses the per-facility outstanding entered in Facility Master Column K.
B9: Days in Year | C9: 365 | D9: days | E9: Used throughout the Interest Schedule in the formula: Opening Balance × Rate × Days / 365.
B10: Financial Basis (drives covenant actuals) | C10: Projected | D10: Basis | E10: Toggle determines which financial column populates the Section C 'Active' values that feed the Covenant Tracker. 'Actual' uses FY24A audited figures; 'Projected' uses FY26E forecast figures.
B11: B. Benchmark Rates (yellow = user input with current market rate)
B12: Benchmark | C12: Current Rate | E12: Source / Notes
B13: 3M T-Bill | C13: 0.0518 | E13: 3M T-Bill yield, Apr 17 2026. Source: tradingeconomics.com (India 3-Month Bond Yield)
B14: Repo Rate (RBI) | C14: 0.0525 | E14: RBI Policy Repo Rate, unchanged in Apr 8 2026 MPC. Source: RBI Monetary Policy Statement, Apr 8 2026
B15: RBL 1Y MCLR | C15: 0.09 | E15: RBL Bank 1Y MCLR, ~9.00% approx Apr 2026. Source: Business Today article Apr 2026 (referenced RBL/YBL MCLR ~9.00%)
B16: YBL 3M MCLR | C16: 0.09 | E16: YES Bank 3M MCLR, ~9.00% approx Apr 2026. Source: Business Today article Apr 2026 (referenced RBL/YBL MCLR ~9.00%)
B17: ICICI 6M I-MCLR | C17: 0.083 | E17: ICICI Bank 6M I-MCLR, effective Jan 22 2026. Source: mymoneymantra.com / codeforbanks.com (ICICI Bank MCLR page)
B18: SIB 12M MCLR | C18: 0.0975 | E18: SIB 12M MCLR (at 21-Jun-2025 sanction; update for latest). Source: SIB sanction letter 21-Jun-2025 (pre-filled; update from southindianbank.com)
B19: Bajaj Floating Reference Rate | C19: 0.085 | E19: Bajaj Floating Reference Rate (at 18-Aug-2025 sanction). Source: Bajaj sanction letter 18-Aug-2025 (pre-filled; update from bajajfinserv.in)
B20: Term SOFR (USD) | C20: 0.043 | E20: Term SOFR 3M, approx. (O/N SOFR 3.67% Apr 16 2026 + term premium). Source: sofrrate.com (overnight SOFR); 3M Term SOFR slightly higher
B21: FD Rate (RBL FDOD) | E21: Customer-specific FD rate backing RBL FDOD. Source required: ask RBL relationship manager for the specific FD rate
B23: C. Latest Management Financials (yellow = user input, INR Cr)
B24: Line Item | C24: Active (driven by toggle) | D24: FY24A (Audited — JCL Standalone Model, Nov-2025) | E24: FY26E (Projected — Mentor Nov-2025 model)
B25: EBITDA (TTM or FY) | C25: =IF(FinancialBasis="Actual",D25,E25) -> 383.96 | D25: 173.37 | E25: 383.96
B26: Total Debt (Gross) | C26: =IF(FinancialBasis="Actual",D26,E26) -> 613.03 | D26: 471.82 | E26: 613.03
B27: Term Debt | C27: =IF(FinancialBasis="Actual",D27,E27) -> 431.28 | D27: 324.01 | E27: 431.28
B28: Tangible Net Worth (TNW) | C28: =IF(FinancialBasis="Actual",D28,E28) -> 740.13 | D28: 720.11 | E28: 740.13
B29: Adjusted TNW (ATNW) | C29: =IF(FinancialBasis="Actual",D29,E29) -> 720.76 | D29: 588.29 | E29: 720.76
B30: Current Assets | C30: =IF(FinancialBasis="Actual",D30,E30) -> 755.02 | D30: 711.3 | E30: 755.02
B31: Current Liabilities | C31: =IF(FinancialBasis="Actual",D31,E31) -> 544.79 | D31: 513.82 | E31: 544.79
B32: Total Outside Liabilities (TOL) | C32: =IF(FinancialBasis="Actual",D32,E32) -> 1143.49 | D32: 1143.77 | E32: 1143.49
B33: Interest Expense (TTM) | C33: =IF(FinancialBasis="Actual",D33,E33) -> 49.08 | D33: 39.87 | E33: 49.08
B34: Fixed Assets (net block) | C34: =IF(FinancialBasis="Actual",D34,E34) -> 937.69 | D34: 449.34 | E34: 937.69
B35: Secured Debt (outstanding) | C35: =IF(FinancialBasis="Actual",D35,E35) -> 431.28 | D35: 324.01 | E35: 431.28
B36: External Rating | C36: =IF(FinancialBasis="Actual",D36,E36) -> CARE A+; Stable / A1 | D36: CARE A+; Stable / A1 | E36: CARE A+; Stable / A1
B37: Promoter Shareholding % | C37: 1 | D37: 1 | E37: 1
B38: Principal Repayment (TTM) | C38: =IF(FinancialBasis="Actual",D38,E38) -> 170.07 | D38: 18.76 | E38: 170.07
B39: Tax Paid (TTM) | C39: 69.36 | E39: 69.36
B40: Scheduled TL Repayment (next 12M) | C40: 41.09 | E40: 41.09
B42: D. Hard Inputs — where they live in this model | C42: (See individual tabs — Facility Master Col K for Current Outstanding, Col W for Drawdown, Col Q for Rate; Instructions Section B for Benchmarks; Instructions Section C for Financials.)
B43: G. Live Data Sources (captured from public data)
B44: Data Point | C44: Value Used | D44: As-of Date | E44: Source
...

Sheet Debt Pricing Table
B2: DEBT PRICING TABLE
B3: Comprehensive rate structure for all 34 facilities. Yellow cells = assumption inputs where rate is "To Be Decided".
B5: S.No | C5: Lender | D5: Facility | E5: Category | F5: Rate Type | G5: Benchmark Index | H5: Benchmark Rate | I5: Spread (bps) | J5: Effective Rate (p.a.) | K5: Reset Frequency | L5: Penal Interest | M5: Rate Source | N5: Status
B6: ='Facility Master'!B5 -> 1 | C6: ='Facility Master'!C5 -> RBL Bank | D6: ='Facility Master'!D5 -> Letter of Credit - Main Limit | E6: ='Facility Master'!E5 -> NFB | F6: ='Facility Master'!R5 -> Fixed | G6: ='Facility Master'!O5 -> Fixed commission | H6: =IFERROR(IF('Facility Master'!O5="1Y MCLR (RBL Bank)",BMK_1Y_MCLR_RBL,IF('Facility Master'!O5="3M MCLR (YBL)",BMK_3M_MCLR_YBL,IF('Facility Master'!O5="6M I-MCLR (ICICI)",BMK_6M_IMCLR_ICICI,IF('Facility Master'!O5="12M MCLR (SIB)",BMK_12M_MCLR_SIB,IF('Facility Master'!O5="Bajaj Floating Reference Rate (BFRR)",BMK_BFRR,IF('Facility Master'!O5="Term SOFR (USD)",BMK_TERM_SOFR,IF('Facility Master'!O5="Repo Rate",BMK_REPO,IF('Facility Master'!O5="FD rate",BMK_FD_RATE,IF('Facility Master'!O5="3M T-Bill",BMK_3M_TBILL,"-"))))))))),"-") -> - | I6: =IFERROR('Facility Master'!P5*10000,"-") -> - | J6: ='Facility Master'!Q5 -> 0.0045 | K6: =IF('Facility Master'!R5="Floating","Quarterly",IF('Facility Master'!R5="Fixed","N/A",IF('Facility Master'!R5="TBD","TBD","N/A"))) -> N/A | L6: N/A | M6: ='Facility Master'!AE5 -> Pricing revised from 0.50% to 0.45% on 31-Dec-2025. | Validity rolled +1 year (orig: 2025-11-30) per Assumption #12: annual-renewal WC facilities presumed operationally renewed. Confirm with relationship manager. | N6: =IF('Facility Master'!Q5=0,IF('Facility Master'!R5="TBD","⚠ Rate TBD","⚠ Rate Missing"),IF('Facility Master'!R5="Floating (Indicative)","⚠ Indicative","✓ Confirmed")) -> ✓ Confirmed
B7: ='Facility Master'!B6 -> 2 | C7: ='Facility Master'!C6 -> RBL Bank | D7: ='Facility Master'!D6 -> Bank Guarantee | E7: ='Facility Master'!E6 -> NFB | F7: ='Facility Master'!R6 -> Fixed | G7: ='Facility Master'!O6 -> Fixed commission | H7: =IFERROR(IF('Facility Master'!O6="1Y MCLR (RBL Bank)",BMK_1Y_MCLR_RBL,IF('Facility Master'!O6="3M MCLR (YBL)",BMK_3M_MCLR_YBL,IF('Facility Master'!O6="6M I-MCLR (ICICI)",BMK_6M_IMCLR_ICICI,IF('Facility Master'!O6="12M MCLR (SIB)",BMK_12M_MCLR_SIB,IF('Facility Master'!O6="Bajaj Floating Reference Rate (BFRR)",BMK_BFRR,IF('Facility Master'!O6="Term SOFR (USD)",BMK_TERM_SOFR,IF('Facility Master'!O6="Repo Rate",BMK_REPO,IF('Facility Master'!O6="FD rate",BMK_FD_RATE,IF('Facility Master'!O6="3M T-Bill",BMK_3M_TBILL,"-"))))))))),"-") -> - | I7: =IFERROR('Facility Master'!P6*10000,"-") -> - | J7: ='Facility Master'!Q6 -> 0.005 | K7: =IF('Facility Master'!R6="Floating","Quarterly",IF('Facility Master'!R6="Fixed","N/A",IF('Facility Master'!R6="TBD","TBD","N/A"))) -> N/A | L7: N/A | M7: ='Facility Master'!AE6 -> Pricing per 28-Feb-2025 table; BG not re-priced on 31-Dec-2025. | Validity rolled +1 year (orig: 2025-11-30) per Assumption #12: annual-renewal WC facilities presumed operationally renewed. Confirm with relationship manager. | ⚠ COMMISSION RATE TBD: Original RBL sanction (25-Nov-2022) specifies 1.00% p.a. for BGs. 31-Dec-2025 renewal does not explicitly revise BG rate downward. 0.50% is inferred from the 28-Feb-2025 pricing table but NOT confirmed in writing by RBL for the renewed sanction. Confirm 0.50% with RBL RM before finalising lender reporting / commission accrual. | N7: =IF('Facility Master'!Q6=0,IF('Facility Master'!R6="TBD","⚠ Rate TBD","⚠ Rate Missing"),IF('Facility Master'!R6="Floating (Indicative)","⚠ Indicative","✓ Confirmed")) -> ✓ Confirmed
